Workbook
Name _3Markup: 'Bang bao gia'!#REF!
Name _3Markup: #REF!
Name CableImport: #REF!
Name CableImport: #REF!
Name Cdiscount: '[1]D) Cabling Installation'!#REF!
Name Cdiscount: '[1]D) Cabling Installation'!#REF!
Name COGS: #REF!
Name COGS: #REF!
Name Customs: #REF!
Name Customs: #REF!
Name Discount: 'Bang bao gia'!#REF!
Name Discount: #REF!
Name DiscountP: '[1]D) Cabling Installation'!#REF!
Name DiscountP: '[1]D) Cabling Installation'!#REF!
Name Exchange: '[1]D) Cabling Installation'!#REF!
Name Exchange: '[1]D) Cabling Installation'!#REF!
Name FOB: '[1]D) Cabling Installation'!#REF!
Name FOB: '[1]D) Cabling Installation'!#REF!
Name Freight: #REF!
Name Freight: #REF!
Name Import: 'Bang bao gia'!#REF!
Name Import: #REF!
Name Margin: '[1]D) Cabling Installation'!#REF!
Name Margin: '[1]D) Cabling Installation'!#REF!
Name Markup: 'Bang bao gia'!#REF!
Name Markup: #REF!
Name nghiagia: 'Bang bao gia'!#REF!
Name nghiagia: #REF!
Name PCMarkup: 'Bang bao gia'!#REF!
Name PCMarkup: #REF!
Name Rack: #REF!
Name Rack: #REF!
Name Service: 'Bang bao gia'!#REF!
Name Service: #REF!
Name Sing: '[1]D) Cabling Installation'!#REF!
Name Sing: '[1]D) Cabling Installation'!#REF!
Name Tax: 'Bang bao gia'!#REF!
Name Tax: #REF!

Sheet Bia
I2: HƯỚNG DẪN SỬ DỤNG
J3: Chỉ điền thông tin ở đây,
B4: Công trình: XYZ | F4: tên công trình | J4: KHÔNG SỬA TRONG SHEET
B5: Mã số CT: | F5: đặt tên: Năm/ Tháng/ Ngày-Tên | J5: Xóa Hướng dẫn này trong file khi gửi khách
B6: Công việc: | F6: điền Tháo dỡ/ Thi công/ Vệ sinh
B7: Ngày: | F7: Điền ngày báo giá
B8: Địa chỉ: | F8: Điền địa chỉ công trình
B9: Bên B: CÔNG TY TNHH THƯƠNG MẠI DỊCH VỤ Ý ÂN
B10: Đại diện bởi Bà: Trần Phạm Ngọc Trân
B11: Chức vụ: Phó Giám đốc
B12: Địa chỉ: 256/41 Nguyễn Tiểu La, Phường Diên Hồng, TP.HCM
B13: Mã số thuế: 0319016318
B14: Điện thoại: 0975460430
B18: Bên A: | C18: ABC
B19: Đại diện bởi .
B20: Chức vụ: .
B21: Địa chỉ:
B22: Mã số thuế: .
B23: Điện thoại: …...........
B24: Fax: ………………..

Sheet Bang bao gia
A1: BẢNG BÁO GIÁ
A2: =Bia!B4 -> Công trình: XYZ | G2: =Bia!B5 -> Mã số CT:
A3: =Bia!B8 -> Địa chỉ: | G3: =Bia!B7 -> Ngày:
A4: =Bia!B6 -> Công việc:
B5: Chúng tôi gồm có:
A6: 1. | B6: =Bia!B18 -> Bên A:
B7: =Bia!B19 -> Đại diện bởi . | F7: =Bia!B20 -> Chức vụ: .
B8: =Bia!B20 -> Chức vụ: .
B9: =Bia!B21 -> Địa chỉ:
B10: =Bia!B22 -> Mã số thuế: . | C10: =Bia!B24 -> Fax: ………………..
B12: =Bia!B9 -> Bên B: CÔNG TY TNHH THƯƠNG MẠI DỊCH VỤ Ý ÂN
B13: =Bia!B10 -> Đại diện bởi Bà: Trần Phạm Ngọc Trân | E13: =Bia!B11 -> Chức vụ: Phó Giám đốc
B14: =Bia!B12 -> Địa chỉ: 256/41 Nguyễn Tiểu La, Phường Diên Hồng, TP.HCM
B15: =Bia!B13 -> Mã số thuế: 0319016318
B16: =Bia!B14 -> Điện thoại: 0975460430
A18: 2. | B18: Nội dung báo giá:
A19: a | B19: Bên B đã khảo sát và báo giá khối lượng khối lượng thực tế như sau:
A20: STT | B20: Nội dung công việc | C20: ĐVT | D20: Khối lượng | E20: Đơn giá chưa bao gồm VAT | F20: Thành tiền | G20: Ghi chú
A21: I | B21: CÔNG TÁC CHUẨN BỊ
A22: 1.1 | B22: Bảo hiểm công trình | C22: gói | F22: =E22*D22 -> 0
A23: 1.2 | B23: Đóng hoarding | C23: m2 | F23: =E23*D23 -> 0
A24: II | B24: HẠNG MỤC TRẦN
A25: 2.1 | B25: Tháo trần thạch cao | C25: m2 | F25: =E25*D25 -> 0
A26: III | B26: HẠNG MỤC VÁCH
A27: 3.1 | B27: Tháo vách kho | C27: m2 | F27: =E27*D27 -> 0
A28: =A27+0.1 -> 3.2 | B28: Tháo cửa cuốn | C28: cái | F28: =E28*D28 -> 0
A29: =A28+0.1 -> 3.3 | B29: Tháo mặt dựng | C29: gói | F29: =E29*D29 -> 0
A30: IV | B30: HẠNG MỤC SÀN | F30: =E30*D30 -> 0
A31: 1 | B31: Đục sàn | C31: m2 | F31: =E31*D31 -> 0
A32: =A31+0.1 -> 1.1 | B32: Cán sàn | C32: m2 | F32: =E32*D32 -> 0
A33: V | B33: HẠNG MỤC SƠN NƯỚC
A34: 5.1 | B34: Sơn nước | C34: m2 | F34: =E34*D34 -> 0
A35: VI | B35: HẠNG MỤC ĐIỆN LẠNH
A36: 6.1 | B36: Cố định đầu cứu hỏa về theo tiêu chuẩn tòa nhà | C36: đầu | F36: =E36*D36 -> 0
A37: 6.2 | B37: Cố định lạnh hồi | C37: đầu | F37: =E37*D37 -> 0
A38: 6.3 | B38: Cố định đầu báo khói | C38: đầu | F38: =E38*D38 -> 0
A39: 6.4 | B39: Trả điện về nguồn | C39: gói | F39: =E39*D39 -> 0
A40: VII | B40: HẠNG MỤC VẬN CHUYỂN
A41: 7.1 | B41: Bên Ý ÂN hỗ trợ chuyển quầy kệ từ gian hàng cho lên xe, bên Minigood chuyển đi | C41: gói | F41: =E41*D41 -> 0
A42: Tổng cộng trước thuế: | F42: =SUBTOTAL(9,F21:F39) -> 0
...

Sheet Biên bảng nghiệm thu
A1: BIÊN BẢN NGHIỆM THU KHỐI LƯỢNG CÔNG VIỆC
A3: =Bia!B4 -> Công trình: XYZ | F3: =Bia!B5 -> Mã số CT:
A4: =Bia!B8 -> Địa chỉ: | F4: Ngày: /07/2026
A5: =Bia!B6 -> Công việc:
A7: Chúng tôi gồm có: | H7: .
A8: =Bia!B18 -> Bên A:
A9: =Bia!B19 -> Đại diện bởi . | D9: =Bia!B20 -> Chức vụ: .
A10: =Bia!B21 -> Địa chỉ:
A11: =Bia!B22 -> Mã số thuế: .
A12: =Bia!B23 -> Điện thoại: …........... | D12: =Bia!B24 -> Fax: ………………..
A14: =Bia!B9 -> Bên B: CÔNG TY TNHH THƯƠNG MẠI DỊCH VỤ Ý ÂN
A15: =Bia!B10 -> Đại diện bởi Bà: Trần Phạm Ngọc Trân | D15: =Bia!B11 -> Chức vụ: Phó Giám đốc
A16: =Bia!B12 -> Địa chỉ: 256/41 Nguyễn Tiểu La, Phường Diên Hồng, TP.HCM
A17: =Bia!B13 -> Mã số thuế: 0319016318
A18: =Bia!B14 -> Điện thoại: 0975460430
A20: 2. | B20: Nội dung nghiệm thu:
A21: a. | B21: Nghiệm thu về việc tháo dỡ hoàn trả mặt bằng cho công trình MiniGood L3-14C Vincom Mega Mall, 161 Võ Nguyên Giáp, Phường An Khánh, TP.HCM của bên A
B22: Bên B đã bàn giao các hạng mục theo công việc với khối lượng thực tế như sau:
A23: Stt | B23: Mô tả công việc | C23: ĐVT | D23: Khối Lượng hợp đồng | E23: Khối Lượng nghiệm thu | F23: % Hoàn thành | G23: Ghi chú | J23: .
A24: I | B24: CÔNG TÁC CHUẨN BỊ
A25: 1.1 | B25: Bảo hiểm công trình | C25: gói | F25: 1
A26: 1.2 | B26: Đóng hoarding | C26: m2 | F26: 1
A27: II | B27: HẠNG MỤC TRẦN
A28: 2.1 | B28: Tháo trần thạch cao | C28: m2 | F28: 1
A29: III | B29: HẠNG MỤC VÁCH
A30: 3.1 | B30: Tháo vách kho | C30: m2 | F30: 1
A31: =A30+0.1 -> 3.2 | B31: Tháo cửa cuốn | C31: cái | F31: 1
A32: =A31+0.1 -> 3.3 | B32: Tháo mặt dựng | C32: gói | F32: 1
A33: IV | B33: HẠNG MỤC SÀN
A34: 1 | B34: Đục sàn | C34: m2 | F34: 1
A35: =A34+0.1 -> 1.1 | B35: Cán sàn | C35: m2 | F35: 1
A36: V | B36: HẠNG MỤC SƠN NƯỚC
A37: 5.1 | B37: Sơn nước | C37: m2 | F37: 1
A38: VI | B38: HẠNG MỤC ĐIỆN LẠNH
A39: 6.1 | B39: Cố định đầu cứu hỏa về theo tiêu chuẩn tòa nhà | C39: đầu | F39: 1
A40: 6.2 | B40: Cố định lạnh hồi | C40: đầu | F40: 1
A41: 6.3 | B41: Cố định đầu báo khói | C41: đầu | F41: 1
A42: 6.4 | B42: Trả điện về nguồn | C42: gói | F42: 1
A43: VII | B43: HẠNG MỤC VẬN CHUYỂN
A44: 7.1 | B44: Bên Ý ÂN hỗ trợ chuyển quầy kệ từ gian hàng cho lên xe, bên Minigood chuyển đi | C44: gói | F44: 1
...

Sheet quyết toán khối lượng
A1: BẢNG GIÁ TRỊ QUYẾT TOÁN KHỐI LƯỢNG
A2: =Bia!B4 -> Công trình: XYZ | H2: =Bia!B5 -> Mã số CT:
A3: =Bia!B8 -> Địa chỉ: | H3: Ngày: /07/2026
A4: =Bia!B6 -> Công việc:
B5: Chúng tôi gồm có:
A6: 1. | B6: =Bia!B18 -> Bên A:
B7: =Bia!B19 -> Đại diện bởi .
B8: =Bia!B20 -> Chức vụ: .
B9: =Bia!B21 -> Địa chỉ:
B10: =Bia!B22 -> Mã số thuế: .
B11: =Bia!B23 -> Điện thoại: …...........
B12: =Bia!B24 -> Fax: ………………..
B14: =Bia!B9 -> Bên B: CÔNG TY TNHH THƯƠNG MẠI DỊCH VỤ Ý ÂN
B15: =Bia!B10 -> Đại diện bởi Bà: Trần Phạm Ngọc Trân
B16: =Bia!B11 -> Chức vụ: Phó Giám đốc
B17: =Bia!B12 -> Địa chỉ: 256/41 Nguyễn Tiểu La, Phường Diên Hồng, TP.HCM
B18: =Bia!B13 -> Mã số thuế: 0319016318
B19: =Bia!B14 -> Điện thoại: 0975460430
A21: 2. | B21: Nội dung quyết toán
B22: Sau khi xem xét thực tế, hai bên tiến hành nghiệm thu và quyết toán khối lượng công việc như sau
A24: Stt | B24: Mô tả công việc | C24: ĐVT | D24: Đơn giá | E24: Khối Lượng Hợp Đồng | F24: Thành Tiền Hợp Đồng | G24: Khối Lượng Thực Tế | H24: Thành Tiền Thực Tế | I24: Ghi chú
A25: I | B25: CÔNG TÁC CHUẨN BỊ
A26: 1.1 | B26: Bảo hiểm công trình | C26: gói
A27: 1.2 | B27: Đóng hoarding | C27: m2 | F27: =E27*D27 -> 0 | H27: =G27*D27 -> 0
A28: II | B28: HẠNG MỤC TRẦN
A29: 2.1 | B29: Tháo trần thạch cao | C29: m2 | F29: =E29*D29 -> 0 | H29: =G29*D29 -> 0
A30: III | B30: HẠNG MỤC VÁCH
A31: 3.1 | B31: Tháo vách kho | C31: m2 | F31: =E31*D31 -> 0 | H31: =G31*D31 -> 0
A32: =A31+0.1 -> 3.2 | B32: Tháo cửa cuốn | C32: cái | F32: =E32*D32 -> 0 | H32: =G32*D32 -> 0
A33: =A32+0.1 -> 3.3 | B33: Tháo mặt dựng | C33: gói | F33: =E33*D33 -> 0 | H33: =G33*D33 -> 0
A34: IV | B34: HẠNG MỤC SÀN
A35: 1 | B35: Đục sàn | C35: m2 | F35: =E35*D35 -> 0 | H35: =G35*D35 -> 0
A36: =A35+0.1 -> 1.1 | B36: Cán sàn | C36: m2 | F36: =E36*D36 -> 0 | H36: =G36*D36 -> 0
A37: V | B37: HẠNG MỤC SƠN NƯỚC
A38: 5.1 | B38: Sơn nước | C38: m2 | F38: =E38*D38 -> 0 | H38: =G38*D38 -> 0
A39: VI | B39: HẠNG MỤC ĐIỆN LẠNH
A40: 6.1 | B40: Cố định đầu cứu hỏa về theo tiêu chuẩn tòa nhà | C40: đầu | F40: =E40*D40 -> 0 | H40: =G40*D40 -> 0
A41: 6.2 | B41: Cố định lạnh hồi | C41: đầu | F41: =E41*D41 -> 0 | H41: =G41*D41 -> 0
A42: 6.3 | B42: Cố định đầu báo khói | C42: đầu | F42: =E42*D42 -> 0 | H42: =G42*D42 -> 0
A43: 6.4 | B43: Trả điện về nguồn | C43: gói | F43: =E43*D43 -> 0 | H43: =G43*D43 -> 0
...

Sheet đề nghị thanh toán
A2: CỘNG HÒA XÃ HỘI CHỦ NGHĨA VIỆT NAM
A3: Độc lập – Tự do – Hạnh phúc
A4: ---------------------
B5: TP.HCM, ngày….. tháng ….. năm 2026
B7: GIẤY ĐỀ NGHỊ THANH TOÁN
B9: Kính gửi: | C9: =Bia!C18 -> ABC
B10: Địa chỉ: | C10: =Bia!C21 -> 0
B11: Công trình: | C11: =Bia!C4 -> 0
B12: Hạng mục: Tháo dỡ hoàn trả mặt bằng | C12: =Bia!C6 -> 0
B13: Căn cứ vào biên bản nghiệm thu công trình giữa bên A và bên B
B14: Căn cứ vào biên bản quyết toán khối lượng
B15: Căn cứ vào biên bản quyết toán
B16: Công ty TNHH THƯƠNG MẠI DỊCH VỤ Ý ÂN đề nghị Quý CÔNG TY …. thanh toán cho
B17: Chúng tôi số tiền còn lại là:….... VND (Bằng chữ: …...........đồng)
B18: Qúy công ty chuyển khoản theo thông tin sau:
B19: Tên tài khoản: CÔNG TY TNHH THƯƠNG MẠI DỊCH VỤ Ý ÂN
B20: Số tài khoản: 795838658
B21: Tại NH: Asia Commercial Bank (ACB)- Phòng giao dịch Nguyễn Tri Phương - HCM
B22: Rất mong sự hợp tác của Quý Công ty.
B23: Trân trọng cảm ơn !
C25: Bà: Trần Phạm Ngọc Trân - Phó Giám Đốc

Sheet Sheet1
A1: CỘNG HÒA XÃ HỘI CHỦ NGHĨA VIỆT NAM
A2: ĐỘC LẬP - TỰ DO - HẠNH PHÚC
A3: ____________________
A5: BIÊN BẢN QUYẾT TOÁN
A6: Công trình: Bread Talk
A7: Hạng mục: hoàn trả mặt bằng
A8: Địa chỉ: B3-15A, TTTM Vincom Center, 72 Lê Thánh Tôn, Phường Sài Gòn, TP.HCM
A10: Bên A: CÔNG TY CỔ PHẦN BÌNH MINH TOÀN CẦU
A11: Đại diện bởi: TRẦN KHÁNH VÂN | F11: Chức vụ: Phó Tổng Giám Đốc
A12: Địa chỉ: 121 (R2-04) đường 10 Tây, khu Nam Quang 1 (H29), Phường Tân Hưng, Thành phố Hồ Chí Minh, Việt Nam
A13: Mã số thuế: 0309554620
A14: Điện thoại: 028 37751727 | E14: Fax: ………………..
A16: Bên B: CÔNG TY TNHH THƯƠNG MẠI DỊCH VỤ Ý ÂN
A17: Đại diện bởi Bà: Trần Phạm Ngọc Trân
A18: Địa chỉ: 256/41 Nguyễn Tiểu La, Phường Diên Hồng, TP.HCM
A19: Mã số thuế :0319016318
A20: Điện thoại: 0975460430
A22: Hôm nay ngày /07/2026, Chúng tôi cùng đồng ý ký kết biên bản quyết toán công trình giữa hai bên A và B với nội dung như sau:
A24: A- | B24: Tổng giá trị hợp đồng đã bao gồm VAT: | G24: 114415740
A25: B- | B25: Tổng giá trị quyết toán khối lượng đã bao gồm VAT: | G25: 135151740
A26: C- | B26: Số tiền bên A đã thanh toán cho bên B đợt 1: | G26: 74158350
A27: D- | B27: Giá trị hóa đơn GTGT bên B đã xuất và đã giao cho bên A (gồm VAT): | G27: 0
A28: E- | B28: Tổng số tiền bên A phải thanh toán tiếp cho bên B: | G28: =G25-G26 -> 60993390
A30: Chúng tôi đã đọc và đồng ý với nội dung trong biên bản này.
A32: Biên bản này được lập thành 02 bản, mỗi bên giữ 01 bản và có giá trị pháp lý như nhau.
C35: Đại diện bên A | F35: Đại diện bên B
F40: Bà: Trần Phạm Ngọc Trân - Phó Giám Đốc
